Workbook

Sheet Sheet1
I7: 伊利纯牛奶（250ml × 24盒/箱）完整BOM清单
I8: 层级 | J8: 物料名称 | K8: 规格/描述 | L8: 单位用量 | M8: 单位 | N8: 来源 | O8: 备注
I9: 0 | J9: 伊利纯牛奶 | K9: 250ml × 24盒 箱装 | L9: 1 | M9: 箱 | N9: 自制
I10: 1 | J10: 伊利纯牛奶 | K10: 250ml 利乐砖，单盒 | L10: 24 | M10: 盒 | N10: 自制 | O10: 最小零售单元
I11: 1 | J11: 外纸箱 | K11: B楞对口箱，可容纳24盒 | L11: 1 | M11: 个 | N11: 外购 | O11: 由纸箱厂供应
I12: 1 | J12: 封箱胶带 | K12: BOPP材质 | L12: 0.5 | M12: 米 | N12: 外购 | O12: 用于封装纸箱
I13: 2 | J13: 外纸箱 | K13: 外购 | L13: 1 | M13: 个 | N13: 外购
I14: 2 | J14: 塑料提手 | K14: 外购 | L14: 1 | M14: 个 | N14: 外购
I15: 2 | J15: 标准化纯牛奶 | K15: 乳蛋白≥3.2g/100ml | L15: 0.25 | M15: 升 | N15: 自制 | O15: 经过杀菌等处理
I16: 2 | J16: 利乐无菌砖包材卷 | K16: 6层复合，幅宽适配灌装机 | L16: 0.04 | M16: 千克 | N16: 外购 | O16: 从利乐等采购
I17: 2 | J17: 吸管 | K17: PP材质，长110mm直管 | L17: 1 | M17: 支 | N17: 外购 | O17: 大批量采购
I18: 2 | J18: 热熔胶 | K18: 食品级，贴管用 | L18: 0.2 | M18: 克 | N18: 外购 | O18: 用于将吸管粘附在包装盒上
I19: 3 | J19: 生牛乳 | K19: 蛋白质≥3.0%，脂肪≥3.6% | L19: 0.26 | M19: 升 | N19: 内部供应 | O19: 伊利合作牧场供应

Sheet Sheet2
F14: 月份 | G14: 1 | H14: 2 | I14: 3 | J14: 4 | K14: 5 | L14: 6 | M14: 7
F15: 销售预测 | G15: 10000 | H15: 10000 | I15: 10000 | J15: 10000 | K15: 10000 | L15: 10000 | M15: 10000
F16: 预计库存（期初19000） | G16: =19000+G17-G15 -> 17833 | H16: =G16+H17-H15 -> 16666 | I16: =H16+I17-I15 -> 15499 | J16: =I16+J17-J15 -> 14332 | K16: =J16+K17-K15 -> 13165 | L16: =K16+L17-L15 -> 11998 | M16: =L16+M17-M15 -> 10831
F17: 生产计划大纲 | G17: 8833 | H17: 8833 | I17: 8833 | J17: 8833 | K17: 8833 | L17: 8833 | M17: 8833
F18: 月份 | G18: 8 | H18: 9 | I18: 10 | J18: 11 | K18: 12 | L18: 全年
F19: 销售预测 | G19: 10000 | H19: 10000 | I19: 10000 | J19: 10000 | K19: 10000 | L19: 120000
F20: 预计库存（期初20000） | G20: =M16+G21-G19 -> 9664 | H20: =G20+H21-H19 -> 8497 | I20: =H20+I21-I19 -> 7330 | J20: =I20+J21-J19 -> 6163 | K20: =J20+K21-K19 -> 5000 | L20: 目标库存5000
F21: 生产计划大纲 | G21: 8833 | H21: 8833 | I21: 8833 | J21: 8833 | K21: =8833+4 -> 8837 | L21: =SUM(G17:M17,G21:K21) -> 106000
O26: 关键资源 | P26: 单位消耗 | Q26: 备注
O27: 生牛乳/L | P27: 6.24 | Q27: 0.26L/盒×24盒
O28: 利乐无菌砖/kg | P28: 0.96 | Q28: 0.04kg/盒×24盒
O29: 生产工时/h | P29: 0.5 | Q29: 灌装+包装综合工时
O31: 关键资源 | P31: 年度需求（106000箱）
O32: 生牛乳/L | P32: =106000*P27 -> 661440
O33: 利乐无菌砖/kg | P33: =106000*P28 -> 101760
O34: 生产工时/h | P34: =106000*P29 -> 53000

Sheet Sheet3
F12: 期初库存 | G12: 19000
F13: 安全库存 | G13: 5000
F14: 批量增量为 | G14: 30000
F15: 时区 | G15: 需求时区 | I15: 计划时区 | M15: 预测时区
F16: 时段（月） | G16: 1 | H16: 2 | I16: 3 | J16: 4 | K16: 5 | L16: 6 | M16: 7 | N16: 8 | O16: 9 | P16: 10 | Q16: 11 | R16: 12
F17: 预测量 | G17: 0 | H17: 0 | I17: 10000 | J17: 10000 | K17: 10000 | L17: 10000 | M17: 10000 | N17: 10000 | O17: 10000 | P17: 10000 | Q17: 10000 | R17: 10000
F18: 订单量 | G18: 12531 | H18: 9812 | I18: 6545 | J18: 10544 | K18: 12135 | L18: 8556 | M18: 0 | N18: 0 | O18: 0 | P18: 0 | Q18: 0 | R18: 0
F19: 毛需求 | G19: =G18 -> 12531 | H19: =H18 -> 9812 | I19: =MAX(I17:I18) -> 10000 | J19: =MAX(J17:J18) -> 10544 | K19: =MAX(K17:K18) -> 12135 | L19: =MAX(L17:L18) -> 10000 | M19: =M17 -> 10000 | N19: =N17 -> 10000 | O19: =O17 -> 10000 | P19: =P17 -> 10000 | Q19: =Q17 -> 10000 | R19: =R17 -> 10000
F20: 计划接收量 | G20: 0 | H20: 0 | I20: 0 | J20: 0 | K20: 0 | L20: 0 | M20: 0 | N20: 0 | O20: 0 | P20: 0 | Q20: 0 | R20: 0
F21: PAB初值(19000) | G21: =$G$12-G19+G20 -> 6469 | H21: =G24-H19+H20 -> -3343 | I21: =H24-I19+I20 -> 16657 | J21: =I24-J19+J20 -> 6113 | K21: =J24-K19+K20 -> -6022 | L21: =K24-L19+L20 -> 13978 | M21: =L24-M19+M20 -> 3978 | N21: =M24-N19+N20 -> 23978 | O21: =N24-O19+O20 -> 13978 | ... R21: =Q24-R19+R20 -> 13978
F22: 净需求 | G22: =IF(G21-$G$13>0,0,$G$13-G21) -> 0 | H22: =IF(H21-$G$13>0,0,$G$13-H21) -> 8343 | I22: =IF(I21-$G$13>0,0,$G$13-I21) -> 0 | J22: =IF(J21-$G$13>0,0,$G$13-J21) -> 0 | K22: =IF(K21-$G$13>0,0,$G$13-K21) -> 11022 | L22: =IF(L21-$G$13>0,0,$G$13-L21) -> 0 | M22: =IF(M21-$G$13>0,0,$G$13-M21) -> 1022 | N22: =IF(N21-$G$13>0,0,$G$13-N21) -> 0 | ... R22: =IF(R21-$G$13>0,0,$G$13-R21) -> 0
F23: 计划产出量 | G23: =ROUNDUP(G22/$G$14,0)*$G$14 -> 0 | H23: =ROUNDUP(H22/$G$14,0)*$G$14 -> 30000 | I23: =ROUNDUP(I22/$G$14,0)*$G$14 -> 0 | J23: =ROUNDUP(J22/$G$14,0)*$G$14 -> 0 | K23: =ROUNDUP(K22/$G$14,0)*$G$14 -> 30000 | L23: =ROUNDUP(L22/$G$14,0)*$G$14 -> 0 | M23: =ROUNDUP(M22/$G$14,0)*$G$14 -> 30000 | N23: =ROUNDUP(N22/$G$14,0)*$G$14 -> 0 | ... R23: =ROUNDUP(R22/$G$14,0)*$G$14 -> 0
F24: 预计库存量 | G24: =G21+G23 -> 6469 | H24: =H21+H23 -> 26657 | I24: =I21+I23 -> 16657 | J24: =J21+J23 -> 6113 | K24: =K21+K23 -> 23978 | L24: =L21+L23 -> 13978 | M24: =M21+M23 -> 33978 | N24: =N21+N23 -> 23978 | ... R24: =R21+R23 -> 13978
F25: 可供销售ATP | G25: =G12-G18 -> 6469 | H25: =H23-H18-I18-J18 -> 3099 | K25: =K23-K18-L18 -> 9309 | M25: =M23-M18-N18-O18 -> 30000 | P25: =P23-P18-Q18-R18 -> 30000

Sheet 物料需求计划
Z8: 物料号 | AA8: 物料名称 | AB8: 低层码 | AC8: 父项 | AD8: 单位用量 | AE8: 单位 | AF8: 属性 | AG8: 提前期(月) | AH8: 现有量 | AI8: 安全库存 | AJ8: 批量
Z9: A | AA9: 伊利纯牛奶箱装 | AB9: 0 | AD9: 1 | AE9: 箱 | AF9: 自制 | AG9: 1 | AH9: 19000 | AI9: 5000 | AJ9: 30000
Z10: B1 | AA10: 250ml单盒纯牛奶 | AB10: 1 | AC10: A | AD10: 24 | AE10: 盒/箱 | AF10: 自制 | AG10: 1 | AH10: 0 | AI10: 0 | AJ10: 1
Z11: B2 | AA11: 外纸箱 | AB11: 1 | AC11: A | AD11: 1 | AE11: 个/箱 | AF11: 外购 | AG11: 1 | AH11: 0 | AI11: 0 | AJ11: 1
Z12: B3 | AA12: 封箱胶带 | AB12: 1 | AC12: A | AD12: 0.5 | AE12: 米/箱 | AF12: 外购 | AG12: 1 | AH12: 0 | AI12: 0 | AJ12: 1
Z13: C1 | AA13: 纸箱箱体 | AB13: 2 | AC13: B2 | AD13: 1 | AE13: 个/个 | AF13: 外购 | AG13: 1 | AH13: 0 | AI13: 0 | AJ13: 1
Z14: C2 | AA14: 塑料提手 | AB14: 2 | AC14: B2 | AD14: 1 | AE14: 个/个 | AF14: 外购 | AG14: 1 | AH14: 0 | AI14: 0 | AJ14: 1
Z15: C3 | AA15: 标准化纯牛奶 | AB15: 2 | AC15: B1 | AD15: 0.25 | AE15: 升/盒 | AF15: 自制 | AG15: 1 | AH15: 0 | AI15: 0 | AJ15: 1
Z16: C4 | AA16: 利乐无菌砖包材卷 | AB16: 2 | AC16: B1 | AD16: 0.04 | AE16: 千克/盒 | AF16: 外购 | AG16: 1 | AH16: 0 | AI16: 0 | AJ16: 1
A17: 低层码 | B17: 提前期 | C17: 现有量 | D17: 分配量 | E17: 安全库存 | F17: 批量 | G17: 单位 | H17: 物料号 | I17: 项目 | J17: 当前 | K17: 1 | L17: 2 | M17: 3 | N17: 4 | O17: 5 | P17: 6 | Q17: 7 | R17: 8 | S17: 9 | T17: 10 | U17: 11 | V17: 12 | Z17: C5 | AA17: 吸管 | AB17: 2 | AC17: B1 | AD17: 1 | AE17: 支/盒 | AF17: 外购 | AG17: 1 | AH17: 0 | AI17: 0 | AJ17: 1
A18: 0 | B18: 1 | C18: 19000 | D18: 0 | E18: 5000 | F18: 30000 | G18: 箱 | H18: A | I18: MPS计划产出 | J18: 0 | K18: =Sheet3!G23 -> 0 | L18: =Sheet3!H23 -> 30000 | M18: =Sheet3!I23 -> 0 | N18: =Sheet3!J23 -> 0 | O18: =Sheet3!K23 -> 30000 | P18: =Sheet3!L23 -> 0 | Q18: =Sheet3!M23 -> 30000 | R18: =Sheet3!N23 -> 0 | ... V18: =Sheet3!R23 -> 0 | Z18: C6 | AA18: 热熔胶 | AB18: 2 | AC18: B1 | AD18: 0.2 | AE18: 克/盒 | AF18: 外购 | AG18: 1 | AH18: 0 | AI18: 0 | AJ18: 1
I19: MPS计划投入 | J19: =K18 -> 0 | K19: =L18 -> 30000 | L19: =M18 -> 0 | M19: =N18 -> 0 | N19: =O18 -> 30000 | O19: =P18 -> 0 | P19: =Q18 -> 30000 | Q19: =R18 -> 0 | ... U19: =V18 -> 0 | V19: 0 | Z19: D1 | AA19: 生牛乳 | AB19: 3 | AC19: C3 | AD19: 1.04 | AE19: 升/升标准奶 | AF19: 内部供应 | AG19: 1 | AH19: 0 | AI19: 0 | AJ19: 1
A21: 1 | B21: 1 | C21: 0 | D21: 0 | E21: 0 | F21: 1 | G21: 盒 | H21: B1 | I21: 毛需求 | J21: =J19*24 -> 0 | K21: =K19*24 -> 720000 | L21: =L19*24 -> 0 | M21: =M19*24 -> 0 | N21: =N19*24 -> 720000 | O21: =O19*24 -> 0 | P21: =P19*24 -> 720000 | Q21: =Q19*24 -> 0 | ... V21: =V19*24 -> 0
I22: 计划接收量 | J22: 0 | K22: 0 | L22: 0 | M22: 0 | N22: 0 | O22: 0 | P22: 0 | Q22: 0 | R22: 0 | S22: 0 | T22: 0 | U22: 0 | V22: 0
I23: PAB初值 | J23: =C21-D21+J22-J21 -> 0 | K23: =J25+K22-K21 -> -720000 | L23: =K25+L22-L21 -> 0 | M23: =L25+M22-M21 -> 0 | N23: =M25+N22-N21 -> -720000 | O23: =N25+O22-O21 -> 0 | P23: =O25+P22-P21 -> -720000 | Q23: =P25+Q22-Q21 -> 0 | R23: =Q25+R22-R21 -> 0 | ... V23: =U25+V22-V21 -> 0
I24: 净需求 | J24: =IF(J23-$E21>0,0,$E21-J23) -> 0 | K24: =IF(K23-$E21>0,0,$E21-K23) -> 720000 | L24: =IF(L23-$E21>0,0,$E21-L23) -> 0 | M24: =IF(M23-$E21>0,0,$E21-M23) -> 0 | N24: =IF(N23-$E21>0,0,$E21-N23) -> 720000 | O24: =IF(O23-$E21>0,0,$E21-O23) -> 0 | P24: =IF(P23-$E21>0,0,$E21-P23) -> 720000 | Q24: =IF(Q23-$E21>0,0,$E21-Q23) -> 0 | ... V24: =IF(V23-$E21>0,0,$E21-V23) -> 0
I25: 预计库存量PAB | J25: =J23+J26 -> 0 | K25: =K23+K26 -> 0 | L25: =L23+L26 -> 0 | M25: =M23+M26 -> 0 | N25: =N23+N26 -> 0 | O25: =O23+O26 -> 0 | P25: =P23+P26 -> 0 | Q25: =Q23+Q26 -> 0 | ... V25: =V23+V26 -> 0
I26: 计划产出量 | J26: =ROUNDUP(J24/$F21,0)*$F21 -> 0 | K26: =ROUNDUP(K24/$F21,0)*$F21 -> 720000 | L26: =ROUNDUP(L24/$F21,0)*$F21 -> 0 | M26: =ROUNDUP(M24/$F21,0)*$F21 -> 0 | N26: =ROUNDUP(N24/$F21,0)*$F21 -> 720000 | O26: =ROUNDUP(O24/$F21,0)*$F21 -> 0 | P26: =ROUNDUP(P24/$F21,0)*$F21 -> 720000 | Q26: =ROUNDUP(Q24/$F21,0)*$F21 -> 0 | ... V26: =ROUNDUP(V24/$F21,0)*$F21 -> 0
I27: 计划投入量 | J27: =K26 -> 720000 | K27: =L26 -> 0 | L27: =M26 -> 0 | M27: =N26 -> 720000 | N27: =O26 -> 0 | O27: =P26 -> 720000 | P27: =Q26 -> 0 | Q27: =R26 -> 0 | ... V27: =W26 -> 0
A29: 1 | B29: 1 | C29: 0 | D29: 0 | E29: 0 | F29: 1 | G29: 个 | H29: B2 | I29: 毛需求 | J29: =J19*1 -> 0 | K29: =K19*1 -> 30000 | L29: =L19*1 -> 0 | M29: =M19*1 -> 0 | N29: =N19*1 -> 30000 | O29: =O19*1 -> 0 | P29: =P19*1 -> 30000 | Q29: =Q19*1 -> 0 | ... V29: =V19*1 -> 0
I30: 计划接收量 | J30: 0 | K30: 0 | L30: 0 | M30: 0 | N30: 0 | O30: 0 | P30: 0 | Q30: 0 | R30: 0 | S30: 0 | T30: 0 | U30: 0 | V30: 0
I31: PAB初值 | J31: =C29-D29+J30-J29 -> 0 | K31: =J33+K30-K29 -> -30000 | L31: =K33+L30-L29 -> 0 | M31: =L33+M30-M29 -> 0 | N31: =M33+N30-N29 -> -30000 | O31: =N33+O30-O29 -> 0 | P31: =O33+P30-P29 -> -30000 | Q31: =P33+Q30-Q29 -> 0 | R31: =Q33+R30-R29 -> 0 | ... V31: =U33+V30-V29 -> 0
I32: 净需求 | J32: =IF(J31-$E29>0,0,$E29-J31) -> 0 | K32: =IF(K31-$E29>0,0,$E29-K31) -> 30000 | L32: =IF(L31-$E29>0,0,$E29-L31) -> 0 | M32: =IF(M31-$E29>0,0,$E29-M31) -> 0 | N32: =IF(N31-$E29>0,0,$E29-N31) -> 30000 | O32: =IF(O31-$E29>0,0,$E29-O31) -> 0 | P32: =IF(P31-$E29>0,0,$E29-P31) -> 30000 | Q32: =IF(Q31-$E29>0,0,$E29-Q31) -> 0 | ... V32: =IF(V31-$E29>0,0,$E29-V31) -> 0
I33: 预计库存量PAB | J33: =J31+J34 -> 0 | K33: =K31+K34 -> 0 | L33: =L31+L34 -> 0 | M33: =M31+M34 -> 0 | N33: =N31+N34 -> 0 | O33: =O31+O34 -> 0 | P33: =P31+P34 -> 0 | Q33: =Q31+Q34 -> 0 | ... V33: =V31+V34 -> 0
I34: 计划产出量 | J34: =ROUNDUP(J32/$F29,0)*$F29 -> 0 | K34: =ROUNDUP(K32/$F29,0)*$F29 -> 30000 | L34: =ROUNDUP(L32/$F29,0)*$F29 -> 0 | M34: =ROUNDUP(M32/$F29,0)*$F29 -> 0 | N34: =ROUNDUP(N32/$F29,0)*$F29 -> 30000 | O34: =ROUNDUP(O32/$F29,0)*$F29 -> 0 | P34: =ROUNDUP(P32/$F29,0)*$F29 -> 30000 | Q34: =ROUNDUP(Q32/$F29,0)*$F29 -> 0 | ... V34: =ROUNDUP(V32/$F29,0)*$F29 -> 0
I35: 计划投入量 | J35: =K34 -> 30000 | K35: =L34 -> 0 | L35: =M34 -> 0 | M35: =N34 -> 30000 | N35: =O34 -> 0 | O35: =P34 -> 30000 | P35: =Q34 -> 0 | Q35: =R34 -> 0 | ... V35: =W34 -> 0
A36: 1 | B36: 1 | C36: 0 | D36: 0 | E36: 0 | F36: 1 | G36: 米 | H36: B3 | I36: 毛需求 | J36: =J19*0.5 -> 0 | K36: =K19*0.5 -> 15000 | L36: =L19*0.5 -> 0 | M36: =M19*0.5 -> 0 | N36: =N19*0.5 -> 15000 | O36: =O19*0.5 -> 0 | P36: =P19*0.5 -> 15000 | Q36: =Q19*0.5 -> 0 | ... V36: =V19*0.5 -> 0
I37: 计划接收量 | J37: 0 | K37: 0 | L37: 0 | M37: 0 | N37: 0 | O37: 0 | P37: 0 | Q37: 0 | R37: 0 | S37: 0 | T37: 0 | U37: 0 | V37: 0
I38: PAB初值 | J38: =C36-D36+J37-J36 -> 0 | K38: =J40+K37-K36 -> -15000 | L38: =K40+L37-L36 -> 0 | M38: =L40+M37-M36 -> 0 | N38: =M40+N37-N36 -> -15000 | O38: =N40+O37-O36 -> 0 | P38: =O40+P37-P36 -> -15000 | Q38: =P40+Q37-Q36 -> 0 | R38: =Q40+R37-R36 -> 0 | ... V38: =U40+V37-V36 -> 0
I39: 净需求 | J39: =IF(J38-$E36>0,0,$E36-J38) -> 0 | K39: =IF(K38-$E36>0,0,$E36-K38) -> 15000 | L39: =IF(L38-$E36>0,0,$E36-L38) -> 0 | M39: =IF(M38-$E36>0,0,$E36-M38) -> 0 | N39: =IF(N38-$E36>0,0,$E36-N38) -> 15000 | O39: =IF(O38-$E36>0,0,$E36-O38) -> 0 | P39: =IF(P38-$E36>0,0,$E36-P38) -> 15000 | Q39: =IF(Q38-$E36>0,0,$E36-Q38) -> 0 | ... V39: =IF(V38-$E36>0,0,$E36-V38) -> 0
I40: 预计库存量PAB | J40: =J38+J41 -> 0 | K40: =K38+K41 -> 0 | L40: =L38+L41 -> 0 | M40: =M38+M41 -> 0 | N40: =N38+N41 -> 0 | O40: =O38+O41 -> 0 | P40: =P38+P41 -> 0 | Q40: =Q38+Q41 -> 0 | ... V40: =V38+V41 -> 0
I41: 计划产出量 | J41: =ROUNDUP(J39/$F36,0)*$F36 -> 0 | K41: =ROUNDUP(K39/$F36,0)*$F36 -> 15000 | L41: =ROUNDUP(L39/$F36,0)*$F36 -> 0 | M41: =ROUNDUP(M39/$F36,0)*$F36 -> 0 | N41: =ROUNDUP(N39/$F36,0)*$F36 -> 15000 | O41: =ROUNDUP(O39/$F36,0)*$F36 -> 0 | P41: =ROUNDUP(P39/$F36,0)*$F36 -> 15000 | Q41: =ROUNDUP(Q39/$F36,0)*$F36 -> 0 | ... V41: =ROUNDUP(V39/$F36,0)*$F36 -> 0
I42: 计划投入量 | J42: =K41 -> 15000 | K42: =L41 -> 0 | L42: =M41 -> 0 | M42: =N41 -> 15000 | N42: =O41 -> 0 | O42: =P41 -> 15000 | P42: =Q41 -> 0 | Q42: =R41 -> 0 | ... V42: =W41 -> 0
A43: 2 | B43: 1 | C43: 0 | D43: 0 | E43: 0 | F43: 1 | G43: 个 | H43: C1 | I43: 毛需求 | J43: =J35*1 -> 30000 | K43: =K35*1 -> 0 | L43: =L35*1 -> 0 | M43: =M35*1 -> 30000 | N43: =N35*1 -> 0 | O43: =O35*1 -> 30000 | P43: =P35*1 -> 0 | Q43: =Q35*1 -> 0 | ... V43: =V35*1 -> 0
I44: 计划接收量 | J44: 0 | K44: 0 | L44: 0 | M44: 0 | N44: 0 | O44: 0 | P44: 0 | Q44: 0 | R44: 0 | S44: 0 | T44: 0 | U44: 0 | V44: 0
I45: PAB初值 | J45: =C43-D43+J44-J43 -> -30000 | K45: =J47+K44-K43 -> 0 | L45: =K47+L44-L43 -> 0 | M45: =L47+M44-M43 -> -30000 | N45: =M47+N44-N43 -> 0 | O45: =N47+O44-O43 -> -30000 | P45: =O47+P44-P43 -> 0 | Q45: =P47+Q44-Q43 -> 0 | R45: =Q47+R44-R43 -> -30000 | ... V45: =U47+V44-V43 -> 0
I46: 净需求 | J46: =IF(J45-$E43>0,0,$E43-J45) -> 30000 | K46: =IF(K45-$E43>0,0,$E43-K45) -> 0 | L46: =IF(L45-$E43>0,0,$E43-L45) -> 0 | M46: =IF(M45-$E43>0,0,$E43-M45) -> 30000 | N46: =IF(N45-$E43>0,0,$E43-N45) -> 0 | O46: =IF(O45-$E43>0,0,$E43-O45) -> 30000 | P46: =IF(P45-$E43>0,0,$E43-P45) -> 0 | Q46: =IF(Q45-$E43>0,0,$E43-Q45) -> 0 | ... V46: =IF(V45-$E43>0,0,$E43-V45) -> 0
I47: 预计库存量PAB | J47: =J45+J48 -> 0 | K47: =K45+K48 -> 0 | L47: =L45+L48 -> 0 | M47: =M45+M48 -> 0 | N47: =N45+N48 -> 0 | O47: =O45+O48 -> 0 | P47: =P45+P48 -> 0 | Q47: =Q45+Q48 -> 0 | ... V47: =V45+V48 -> 0
I48: 计划产出量 | J48: =ROUNDUP(J46/$F43,0)*$F43 -> 30000 | K48: =ROUNDUP(K46/$F43,0)*$F43 -> 0 | L48: =ROUNDUP(L46/$F43,0)*$F43 -> 0 | M48: =ROUNDUP(M46/$F43,0)*$F43 -> 30000 | N48: =ROUNDUP(N46/$F43,0)*$F43 -> 0 | O48: =ROUNDUP(O46/$F43,0)*$F43 -> 30000 | P48: =ROUNDUP(P46/$F43,0)*$F43 -> 0 | Q48: =ROUNDUP(Q46/$F43,0)*$F43 -> 0 | ... V48: =ROUNDUP(V46/$F43,0)*$F43 -> 0
I49: 计划投入量 | J49: =K48 -> 0 | K49: =L48 -> 0 | L49: =M48 -> 30000 | M49: =N48 -> 0 | N49: =O48 -> 30000 | O49: =P48 -> 0 | P49: =Q48 -> 0 | Q49: =R48 -> 30000 | ... V49: =W48 -> 0
...

Sheet 能力需求计划
A1: 能力需求计划（CRP）编制表
A3: Step 1 分解产品物料需求：由MPS/MRP得到计划订单 | R3: 月份 | S3: 总负荷 | T3: 可用能力
A4: 项目 | B4: 1 | C4: 2 | D4: 3 | E4: 4 | F4: 5 | G4: 6 | H4: 7 | I4: 8 | J4: 9 | K4: 10 | L4: 11 | M4: 12 | N4: 合计 | O4: 说明 | R4: 1 | S4: 0 | T4: 16678.2
A5: MPS计划产出量(箱) | B5: 0 | C5: 30000 | D5: 0 | E5: 0 | F5: 30000 | G5: 0 | H5: 30000 | I5: 0 | J5: 0 | K5: 30000 | L5: 0 | M5: 0 | N5: 120000 | O5: 批量为30000箱，集中在第2、5、7、10月 | R5: 2 | S5: 15000 | T5: 16678.2
A6: 计划投入量(箱) | B6: 0 | C6: 30000 | D6: 0 | E6: 0 | F6: 30000 | G6: 0 | H6: 30000 | I6: 0 | J6: 0 | K6: 30000 | L6: 0 | M6: 0 | N6: 120000 | O6: 提前期按月度计划已在MPS/MRP中处理 | R6: 3 | S6: 0 | T6: 16678.2
A7: CRP计算对象 | C7: 生产批 | F7: 生产批 | H7: 生产批 | K7: 生产批 | N7: 4批 | O7: 进入工艺路线和工作中心负荷计算 | R7: 4 | S7: 0 | T7: 16678.2
R8: 5 | S8: 15000 | T8: 16678.2
R9: 6 | S9: 0 | T9: 16678.2
A10: Step 2 编制工艺路线文件：计算单件总时间 | R10: 7 | S10: 15000 | T10: 16678.2
R11: 8 | S11: 0 | T11: 16678.2
A12: 产品A（伊利纯牛奶箱装）的工艺路线文件（时间单位为定额工时） | R12: 9 | S12: 0 | T12: 16678.2
A13: 物料 | B13: 工序号 | C13: 工作中心 | D13: 工序内容 | E13: 单件加工时间 | F13: 生产准备时间 | G13: 平均批量 | H13: 单件准备时间 | I13: 单件总时间 | R13: 10 | S13: 15000 | T13: 16678.2
A14: A | B14: 101(A-10) | C14: WC-10 | D14: 原奶验收与标准化 | E14: 0.075 | F14: 0.3 | G14: 60 | H14: 0.005 | I14: 0.08 | R14: 11 | S14: 0 | T14: 16678.2
A15: B | B15: 201(B-10) | C15: WC-20 | D15: UHT灭菌 | E15: 0.092 | F15: 0.48 | G15: 60 | H15: 0.008 | I15: 0.1 | R15: 12 | S15: 0 | T15: 16678.2
A16: C | B16: 301(C-10) | C16: WC-30 | D16: 无菌灌装封合 | E16: 0.145 | F16: 0.9 | G16: 60 | H16: 0.015 | I16: 0.16
A17: D | B17: 401(D-10) | C17: WC-40 | D17: 装箱封箱 | E17: 0.094 | F17: 0.36 | G17: 60 | H17: 0.006 | I17: 0.1
A18: E | B18: 501(E-10) | C18: WC-50 | D18: 成品检验与入库 | E18: 0.056 | F18: 0.24 | G18: 60 | H18: 0.004 | I18: 0.06
A19: 合计 | E19: =SUM(E14:E18) -> 0.462 | H19: =SUM(H14:H18) -> 0.038 | I19: =SUM(I14:I18) -> 0.5
A22: Step 3 编制工作中心能力文件：计算可用能力和单批负荷
A23: 工作中心 | B23: 工序内容 | C23: 排队时间(天) | D23: 运输时间(天) | E23: 人数/设备台数 | F23: 月可用能力(h) | G23: 单批30000箱负荷(h) | H23: 生产时间(月) | I23: 负荷率
A24: WC-10 | B24: 原奶验收与标准化 | C24: 1 | D24: 1 | E24: 16 | F24: 2541.44 | G24: 2400 | H24: 0.94434651 | I24: 0.94434651
A25: WC-20 | B25: UHT灭菌 | C25: 1 | D25: 1 | E25: 20 | F25: 3176.8 | G25: 3000 | H25: 0.94434651 | I25: 0.94434651
A26: WC-30 | B26: 无菌灌装封合 | C26: 2 | D26: 1 | E26: 31 | F26: 4924.04 | G26: 4800 | H26: 0.9748093 | I26: 0.9748093
A27: WC-40 | B27: 装箱封箱 | C27: 1 | D27: 1 | E27: 20 | F27: 3176.8 | G27: 3000 | H27: 0.94434651 | I27: 0.94434651
A28: WC-50 | B28: 成品检验与入库 | C28: 1 | D28: 1 | E28: 18 | F28: 2859.12 | G28: 1800 | H28: 0.62956434 | I28: 0.62956434
A29: 合计 | F29: =SUM(F24:F28) -> 16678.2 | G29: =SUM(G24:G28) -> 15000 | H29: =G29/F29 -> 0.89937763 | I29: =G29/F29 -> 0.89937763
A32: Step 4 编制工序计划：按订单月份安排开工与完工
A33: 订单月份 | B33: 订单数量(箱) | C33: WC-10 | D33: WC-20 | E33: WC-30 | F33: WC-40 | G33: WC-50 | H33: 计划说明
A34: 2 | B34: 30000 | C34: 2月上旬 | D34: 2月上旬 | E34: 2月中旬 | F34: 2月中旬 | G34: 2月下旬 | H34: 按月度CRP汇总，生产月份内顺序衔接
A35: 5 | B35: 30000 | C35: 5月上旬 | D35: 5月上旬 | E35: 5月中旬 | F35: 5月中旬 | G35: 5月下旬 | H35: 按月度CRP汇总，生产月份内顺序衔接
A36: 7 | B36: 30000 | C36: 7月上旬 | D36: 7月上旬 | E36: 7月中旬 | F36: 7月中旬 | G36: 7月下旬 | H36: 按月度CRP汇总，生产月份内顺序衔接
A37: 10 | B37: 30000 | C37: 10月上旬 | D37: 10月上旬 | E37: 10月中旬 | F37: 10月中旬 | G37: 10月下旬 | H37: 按月度CRP汇总，生产月份内顺序衔接
A40: Step 5 物料能力需求计划表：按物料/工作中心展开负荷
A41: 物料 | B41: 工作中心 | C41: 拖期 | D41: 1 | E41: 2 | F41: 3 | G41: 4 | H41: 5 | I41: 6 | J41: 7 | K41: 8 | L41: 9 | M41: 10 | N41: 11 | O41: 12 | P41: 总计
A42: A | B42: WC-10 | C42: 0 | D42: 0 | E42: 2400 | F42: 0 | G42: 0 | H42: 2400 | I42: 0 | J42: 2400 | K42: 0 | L42: 0 | M42: 2400 | N42: 0 | O42: 0 | P42: =SUM(D42:O42) -> 9600
A43: B | B43: WC-20 | C43: 0 | D43: 0 | E43: 3000 | F43: 0 | G43: 0 | H43: 3000 | I43: 0 | J43: 3000 | K43: 0 | L43: 0 | M43: 3000 | N43: 0 | O43: 0 | P43: =SUM(D43:O43) -> 12000
A44: C | B44: WC-30 | C44: 0 | D44: 0 | E44: 4800 | F44: 0 | G44: 0 | H44: 4800 | I44: 0 | J44: 4800 | K44: 0 | L44: 0 | M44: 4800 | N44: 0 | O44: 0 | P44: =SUM(D44:O44) -> 19200
A45: D | B45: WC-40 | C45: 0 | D45: 0 | E45: 3000 | F45: 0 | G45: 0 | H45: 3000 | I45: 0 | J45: 3000 | K45: 0 | L45: 0 | M45: 3000 | N45: 0 | O45: 0 | P45: =SUM(D45:O45) -> 12000
A46: E | B46: WC-50 | C46: 0 | D46: 0 | E46: 1800 | F46: 0 | G46: 0 | H46: 1800 | I46: 0 | J46: 1800 | K46: 0 | L46: 0 | M46: 1800 | N46: 0 | O46: 0 | P46: =SUM(D46:O46) -> 7200
A49: Step 6 按工作中心汇总负荷并绘制负荷图
...

Sheet 典型场景调度
A1: 典型场景生产调度计算表
A3: 调度场景 | B3: 第2月30000箱生产批 | C3: 作业类型 | D3: 同序流水作业 | E3: 调度规则 | F3: EDD最早交期优先 | G3: 瓶颈工序 | H3: WC-30无菌灌装封合 | I3: 月工作日 | J3: 22 | K3: 数据来源 | L3: MPS/CRP
A4: 生产批量(箱) | B4: 30000 | C4: 拆分依据 | D4: 客户订单+预测备货+安全库存 | E4: 目标 | F4: 满足交期、控制瓶颈负荷 | G4: 异常假设 | H4: 瓶颈停机1天 | I4: 计划单位 | J4: 工作日
A7: Step 1 订单拆分与优先级计算
A8: 作业编号 | B8: 需求来源 | C8: 数量(箱) | D8: 释放日 | E8: 交期 | F8: EDD顺序 | G8: 瓶颈日能力 | H8: 瓶颈工期 | I8: 开始日 | J8: 完成日 | K8: 拖期 | L8: 状态
A9: J1 | B9: 2月客户确定订单 | C9: 9812 | D9: 0 | E9: 8 | F9: =_xludf.RANK.EQ(E9,$E$9:$E$11,1)+COUNTIF($E$9:E9,E9)-1 -> #NAME? | G9: =$D$22 -> 1398.875 | H9: =C9/G9 -> 7.0142078 | I9: =IF(F9=1,$D$4,INDEX($J$9:$J$11,MATCH(F9-1,$F$9:$F$11,0))) -> #NAME? | J9: =I9+H9 -> #NAME? | K9: =MAX(0,J9-E9) -> #NAME? | L9: =IF(K9=0,"按期","需调整") -> #NAME?
A10: J2 | B10: 3月销售预测备货 | C10: 10000 | D10: 0 | E10: 16 | F10: =_xludf.RANK.EQ(E10,$E$9:$E$11,1)+COUNTIF($E$9:E10,E10)-1 -> #NAME? | G10: =$D$22 -> 1398.875 | H10: =C10/G10 -> 7.1486016 | I10: =IF(F10=1,$D$4,INDEX($J$9:$J$11,MATCH(F10-1,$F$9:$F$11,0))) -> #NAME? | J10: =I10+H10 -> #NAME? | K10: =MAX(0,J10-E10) -> #NAME? | L10: =IF(K10=0,"按期","需调整") -> #NAME?
A11: J3 | B11: 安全库存与批量余量 | C11: 10188 | D11: 0 | E11: 22 | F11: =_xludf.RANK.EQ(E11,$E$9:$E$11,1)+COUNTIF($E$9:E11,E11)-1 -> #NAME? | G11: =$D$22 -> 1398.875 | H11: =C11/G11 -> 7.2829953 | I11: =IF(F11=1,$D$4,INDEX($J$9:$J$11,MATCH(F11-1,$F$9:$F$11,0))) -> #NAME? | J11: =I11+H11 -> #NAME? | K11: =MAX(0,J11-E11) -> #NAME? | L11: =IF(K11=0,"按期","需调整") -> #NAME?
A14: Step 2 工作中心能力与瓶颈识别
A15: 工作中心 | B15: 工序内容 | C15: 单件总时间(h/箱) | D15: 月可用能力(h) | E15: 月可加工能力(箱) | F15: 日可加工能力 | G15: 单批负荷(h) | H15: 负荷率 | I15: 瓶颈判断
A16: WC-10 | B16: 原奶验收与标准化 | C16: 0.08 | D16: 2541.44 | E16: =D16/C16 -> 31768 | F16: =E16/$J$3 -> 1444 | G16: =$B$4*C16 -> 2400 | H16: =G16/D16 -> 0.94434651 | I16: =IF(H16=MAX($H$16:$H$20),"瓶颈","")
A17: WC-20 | B17: UHT灭菌 | C17: 0.1 | D17: 3176.8 | E17: =D17/C17 -> 31768 | F17: =E17/$J$3 -> 1444 | G17: =$B$4*C17 -> 3000 | H17: =G17/D17 -> 0.94434651 | I17: =IF(H17=MAX($H$16:$H$20),"瓶颈","")
A18: WC-30 | B18: 无菌灌装封合 | C18: 0.16 | D18: 4924.04 | E18: =D18/C18 -> 30775.25 | F18: =E18/$J$3 -> 1398.875 | G18: =$B$4*C18 -> 4800 | H18: =G18/D18 -> 0.9748093 | I18: =IF(H18=MAX($H$16:$H$20),"瓶颈","") -> 瓶颈
A19: WC-40 | B19: 装箱封箱 | C19: 0.1 | D19: 3176.8 | E19: =D19/C19 -> 31768 | F19: =E19/$J$3 -> 1444 | G19: =$B$4*C19 -> 3000 | H19: =G19/D19 -> 0.94434651 | I19: =IF(H19=MAX($H$16:$H$20),"瓶颈","")
A20: WC-50 | B20: 成品检验与入库 | C20: 0.06 | D20: 2859.12 | E20: =D20/C20 -> 47652 | F20: =E20/$J$3 -> 2166 | G20: =$B$4*C20 -> 1800 | H20: =G20/D20 -> 0.62956434 | I20: =IF(H20=MAX($H$16:$H$20),"瓶颈","")
A22: 瓶颈工作中心 | B22: =INDEX(A16:A20,MATCH(MAX(H16:H20),H16:H20,0)) -> WC-30 | C22: 瓶颈日能力(箱/日) | D22: =INDEX(F16:F20,MATCH(MAX(H16:H20),H16:H20,0)) -> 1398.875 | E22: 最高负荷率 | F22: =MAX(H16:H20) -> 0.9748093 | G22: 月度余量(天) | H22: =22-MAX(J9:J11) -> #NAME? | I22: 停机1天需补偿(天) | J22: =MAX(0,1-H22) -> #NAME?
A25: Step 3 调度结果汇总
A26: 顺序 | B26: 作业编号 | C26: 需求来源 | D26: 数量(箱) | E26: 交期 | F26: 开始日 | G26: 完成日 | H26: 瓶颈工期 | I26: 拖期 | J26: 执行结论
A27: 1 | B27: =INDEX($A$9:$A$11,MATCH(A27,$F$9:$F$11,0)) -> #N/A | C27: =INDEX($B$9:$B$11,MATCH(A27,$F$9:$F$11,0)) -> #N/A | D27: =INDEX($C$9:$C$11,MATCH(A27,$F$9:$F$11,0)) -> #N/A | E27: =INDEX($E$9:$E$11,MATCH(A27,$F$9:$F$11,0)) -> #N/A | F27: =INDEX($I$9:$I$11,MATCH(A27,$F$9:$F$11,0)) -> #N/A | G27: =INDEX($J$9:$J$11,MATCH(A27,$F$9:$F$11,0)) -> #N/A | H27: =INDEX($H$9:$H$11,MATCH(A27,$F$9:$F$11,0)) -> #N/A | I27: =INDEX($K$9:$K$11,MATCH(A27,$F$9:$F$11,0)) -> #N/A | J27: =IF(I27=0,"按期完成","需加班/调整") -> #N/A
A28: 2 | B28: =INDEX($A$9:$A$11,MATCH(A28,$F$9:$F$11,0)) -> #N/A | C28: =INDEX($B$9:$B$11,MATCH(A28,$F$9:$F$11,0)) -> #N/A | D28: =INDEX($C$9:$C$11,MATCH(A28,$F$9:$F$11,0)) -> #N/A | E28: =INDEX($E$9:$E$11,MATCH(A28,$F$9:$F$11,0)) -> #N/A | F28: =INDEX($I$9:$I$11,MATCH(A28,$F$9:$F$11,0)) -> #N/A | G28: =INDEX($J$9:$J$11,MATCH(A28,$F$9:$F$11,0)) -> #N/A | H28: =INDEX($H$9:$H$11,MATCH(A28,$F$9:$F$11,0)) -> #N/A | I28: =INDEX($K$9:$K$11,MATCH(A28,$F$9:$F$11,0)) -> #N/A | J28: =IF(I28=0,"按期完成","需加班/调整") -> #N/A
A29: 3 | B29: =INDEX($A$9:$A$11,MATCH(A29,$F$9:$F$11,0)) -> #N/A | C29: =INDEX($B$9:$B$11,MATCH(A29,$F$9:$F$11,0)) -> #N/A | D29: =INDEX($C$9:$C$11,MATCH(A29,$F$9:$F$11,0)) -> #N/A | E29: =INDEX($E$9:$E$11,MATCH(A29,$F$9:$F$11,0)) -> #N/A | F29: =INDEX($I$9:$I$11,MATCH(A29,$F$9:$F$11,0)) -> #N/A | G29: =INDEX($J$9:$J$11,MATCH(A29,$F$9:$F$11,0)) -> #N/A | H29: =INDEX($H$9:$H$11,MATCH(A29,$F$9:$F$11,0)) -> #N/A | I29: =INDEX($K$9:$K$11,MATCH(A29,$F$9:$F$11,0)) -> #N/A | J29: =IF(I29=0,"按期完成","需加班/调整") -> #N/A
A33: Step 4 甘特图（蓝色表示占用瓶颈WC-30的工作日）
A34: 作业 | B34: 1 | C34: 2 | D34: 3 | E34: 4 | F34: 5 | G34: 6 | H34: 7 | I34: 8 | J34: 9 | K34: 10 | L34: 11 | M34: 12 | N34: 13 | O34: 14 | P34: 15 | Q34: 16 | R34: 17 | S34: 18 | T34: 19 | U34: 20 | V34: 21 | W34: 22
A35: =A9 -> J1
A36: =A10 -> J2
A37: =A11 -> J3
